seq_dataset 214
seq_dataset_val 234
Train epoch 1/200
  0% 0/1000 [00:00<?, ?it/s]  0% 0/1000 [00:01<?, ?it/s]
Traceback (most recent call last):
  File "/home/zuern/SiamRPN-PyTorch/train/train_siamrpn.py", line 277, in <module>
    main()
  File "/home/zuern/SiamRPN-PyTorch/train/train_siamrpn.py", line 191, in main
    for i, dataset in enumerate(train_loader):
  File "/home/zuern/.local/lib/python3.5/site-packages/torch/utils/data/dataloader.py", line 819, in __next__
    return self._process_data(data)
  File "/home/zuern/.local/lib/python3.5/site-packages/torch/utils/data/dataloader.py", line 846, in _process_data
    data.reraise()
  File "/home/zuern/.local/lib/python3.5/site-packages/torch/_utils.py", line 385, in reraise
    raise self.exc_type(msg)
ValueError: Caught ValueError in DataLoader worker process 0.
Original Traceback (most recent call last):
  File "/home/zuern/.local/lib/python3.5/site-packages/torch/utils/data/_utils/worker.py", line 178, in _worker_loop
    data = fetcher.fetch(index)
  File "/home/zuern/.local/lib/python3.5/site-packages/torch/utils/data/_utils/fetch.py", line 44, in fetch
    data = [self.dataset[idx] for idx in possibly_batched_index]
  File "/home/zuern/.local/lib/python3.5/site-packages/torch/utils/data/_utils/fetch.py", line 44, in <listcomp>
    data = [self.dataset[idx] for idx in possibly_batched_index]
  File "/home/zuern/SiamRPN-PyTorch/train/data_rgbt.py", line 524, in __getitem__
    self.open()
  File "/home/zuern/SiamRPN-PyTorch/train/data_rgbt.py", line 176, in open
    img_ir_mean_d )
  File "/home/zuern/SiamRPN-PyTorch/train/data_rgbt.py", line 222, in get_instance_image
    instance_img, gt_w, gt_h, scale_x, scale_h, scale_w = self.crop_and_pad(img, cx, cy, w, h, a_x, b_y,  size_x, s_x, img_mean)
  File "/home/zuern/SiamRPN-PyTorch/train/data_rgbt.py", line 245, in crop_and_pad
    im_h, im_w, _ = img.shape
ValueError: not enough values to unpack (expected 3, got 2)

