seq_dataset 214
seq_dataset_val 20
Train epoch 1/200
  0% 0/1000 [00:00<?, ?it/s]  0% 0/1000 [00:04<?, ?it/s]
Traceback (most recent call last):
  File "/home/zuern/SiamRPN-PyTorch/train/train.py", line 287, in <module>
    main()
  File "/home/zuern/SiamRPN-PyTorch/train/train.py", line 211, in main
    for i, dataset in enumerate(train_loader):
  File "/home/zuern/.local/lib/python3.5/site-packages/torch/utils/data/dataloader.py", line 819, in __next__
    return self._process_data(data)
  File "/home/zuern/.local/lib/python3.5/site-packages/torch/utils/data/dataloader.py", line 846, in _process_data
    data.reraise()
  File "/home/zuern/.local/lib/python3.5/site-packages/torch/_utils.py", line 385, in reraise
    raise self.exc_type(msg)
RuntimeError: Caught RuntimeError in DataLoader worker process 0.
Original Traceback (most recent call last):
  File "/home/zuern/.local/lib/python3.5/site-packages/torch/utils/data/_utils/worker.py", line 178, in _worker_loop
    data = fetcher.fetch(index)
  File "/home/zuern/.local/lib/python3.5/site-packages/torch/utils/data/_utils/fetch.py", line 47, in fetch
    return self.collate_fn(data)
  File "/home/zuern/.local/lib/python3.5/site-packages/torch/utils/data/_utils/collate.py", line 79, in default_collate
    return [default_collate(samples) for samples in transposed]
  File "/home/zuern/.local/lib/python3.5/site-packages/torch/utils/data/_utils/collate.py", line 79, in <listcomp>
    return [default_collate(samples) for samples in transposed]
  File "/home/zuern/.local/lib/python3.5/site-packages/torch/utils/data/_utils/collate.py", line 55, in default_collate
    return torch.stack(batch, 0, out=out)
RuntimeError: invalid argument 0: Sizes of tensors must match except in dimension 0. Got 122 and 131 in dimension 2 at /pytorch/aten/src/TH/generic/THTensor.cpp:689

