seq_dataset 214
seq_dataset_val 234
Train epoch 1/200
  0% 0/1000 [00:00<?, ?it/s]  0% 0/1000 [00:00<?, ?it/s]
Traceback (most recent call last):
  File "/home/zuern/SiamRPN-PyTorch/train/train_siamrpn.py", line 277, in <module>
    main()
  File "/home/zuern/SiamRPN-PyTorch/train/train_siamrpn.py", line 191, in main
    for i, dataset in enumerate(train_loader):
  File "/home/zuern/.local/lib/python3.5/site-packages/torch/utils/data/dataloader.py", line 819, in __next__
    return self._process_data(data)
  File "/home/zuern/.local/lib/python3.5/site-packages/torch/utils/data/dataloader.py", line 846, in _process_data
    data.reraise()
  File "/home/zuern/.local/lib/python3.5/site-packages/torch/_utils.py", line 385, in reraise
    raise self.exc_type(msg)
ValueError: Caught ValueError in DataLoader worker process 0.
Original Traceback (most recent call last):
  File "/home/zuern/.local/lib/python3.5/site-packages/torch/utils/data/_utils/worker.py", line 178, in _worker_loop
    data = fetcher.fetch(index)
  File "/home/zuern/.local/lib/python3.5/site-packages/torch/utils/data/_utils/fetch.py", line 44, in fetch
    data = [self.dataset[idx] for idx in possibly_batched_index]
  File "/home/zuern/.local/lib/python3.5/site-packages/torch/utils/data/_utils/fetch.py", line 44, in <listcomp>
    data = [self.dataset[idx] for idx in possibly_batched_index]
  File "/home/zuern/SiamRPN-PyTorch/train/data_rgbt.py", line 470, in __getitem__
    self.open()
  File "/home/zuern/SiamRPN-PyTorch/train/data_rgbt.py", line 136, in open
    config.context, img_ir_mean )
  File "/home/zuern/SiamRPN-PyTorch/train/data_rgbt.py", line 203, in get_exemplar_image
    exemplar_img, scale_x = self.crop_and_pad_old(img, cx, cy, size_z, s_z, img_mean)
  File "/home/zuern/SiamRPN-PyTorch/train/data_rgbt.py", line 334, in crop_and_pad_old
    im_h, im_w, _ = img.shape
ValueError: not enough values to unpack (expected 3, got 2)

